<?xml version="1.0"?>
<robot name="spot">

  <!-- Base Link -->
  <link name="base">
    <inertial>
      <origin xyz="0.008465 0.004045 -0.000763" rpy="0 0 0"/>
      <mass value="15.041"/>
      <inertia ixx="0.174606" ixy="0" ixz="0" iyy="0.161174" iyz="0" izz="0.033257"/>
    </inertial>
    <visual>
      <origin xyz="0 0 0" rpy="1.571 1.571 0"/>
      <geometry>
        <mesh filename="package://spot_description/urdf/meshes/base.obj"/>
      </geometry>
      <material name="base"/>
        <color rgba="1 0.8431 0 1" />
      <material/>
    </visual>
    <collision>
      <geometry>
        <sphere radius="0.0335"/>
      </geometry>
    </collision>
    <collision>
      <geometry>
        <box size="0.3935 0.09 0.086"/>
      </geometry>
    </collision>
  </link>

  <!-- Floating Base Joint -->
  <!-- <joint name="floating_base" type="fixed">
    <parent link="base"/>
    <child link="fl_hip"/>
  </joint> -->

  <!-- Front Left Hip -->
  <link name="fl_hip">
    <inertial>
      <origin xyz="-0.022191 0.015144 -1.5e-05" rpy="0 0 0"/>
      <mass value="1.993"/>
      <inertia ixx="0.00558695" ixy="0" ixz="0" iyy="0.00491009" iyz="0" izz="0.00290132"/>
    </inertial>
    <visual>
      <geometry>
        <mesh filename="package://spot_description/urdf/meshes/fl.hip.obj"/>
      </geometry>
      <material name="fl_hip">
        <color rgba="0.2 0.2 0.2 1" />
      </material>
    </visual>
  </link>

  <joint name="fl_hx" type="revolute">
    <parent link="base"/>
    <child link="fl_hip"/>
    <axis xyz="1 0 0"/>
    <limit lower="-0.785398" upper="0.785398" effort="0" velocity="0"/>
  </joint>

  <!-- Front Left Upper Leg -->
  <link name="fl_uleg">
    <inertial>
      <origin xyz="-0.005607 -0.003877 -0.118199" rpy="0 0 0"/>
      <mass value="0.639"/>
      <inertia ixx="0.0058474" ixy="0" ixz="0" iyy="0.00571186" iyz="0" izz="0.000324584"/>
    </inertial>
    <visual>
      <geometry>
        <mesh filename="package://spot_description/urdf/meshes/fl.uleg.obj"/>
      </geometry>
      <material name="fl_uleg">
        <color rgba="1 0.8431 0 1" />
      </material>
    </visual>
    <collision>
      <origin xyz="0 0 -0.125" rpy="0 0 0"/>
      <geometry>
        <box size="0.125 0.0187 0.0215"/>
      </geometry>
    </collision>
  </link>

  <joint name="fl_hy" type="revolute">
    <parent link="fl_hip"/>
    <child link="fl_uleg"/>
    <axis xyz="0 1 0"/>
    <limit lower="-0.898845" upper="2.29511" effort="0" velocity="0"/>
  </joint>

  <!-- Front Left Lower Leg -->
  <link name="fl_lleg">
    <inertial>
      <origin xyz="0.002781 6.3e-05 -0.142518" rpy="0 0 0"/>
      <mass value="0.207"/>
      <inertia ixx="0.0028579" ixy="0" ixz="0" iyy="0.00285516" iyz="0" izz="3.64431e-05"/>
    </inertial>
    <visual>
      <geometry>
        <mesh filename="package://spot_description/urdf/meshes/fl.lleg.obj"/>
      </geometry>
      <material name="fl_lleg">
        <color rgba="0.2 0.2 0.2 1" />
      </material>
    </visual>
    <collision>
      <origin xyz="0 0 -0.335" rpy="0 0 0"/>
      <geometry>
        <sphere radius="0.0335"/>
      </geometry>
    </collision>
    <collision>
      <origin xyz="0 0 -0.125" rpy="0 0 0"/>
      <geometry>
        <box size="0.125 0.0104 0.008"/>
      </geometry>
    </collision>
  </link>

  <joint name="fl_kn" type="revolute">
    <parent link="fl_uleg"/>
    <child link="fl_lleg"/>
    <axis xyz="0 1 0"/>
    <limit lower="-2.7929" upper="-0.254402" effort="0" velocity="0"/>
  </joint>

  <!-- Front Right Hip -->
  <link name="fr_hip">
    <inertial>
      <origin xyz="-0.022191 -0.015144 -1.5e-05" rpy="0 0 0"/>
      <mass value="1.993"/>
      <inertia ixx="0.00558695" ixy="0" ixz="0" iyy="0.00491009" iyz="0" izz="0.00290132"/>
    </inertial>
    <visual>
      <geometry>
        <mesh filename="package://spot_description/urdf/meshes/fr.hip.obj"/>
      </geometry>
      <material name="fr_hip">
        <color rgba="0.2 0.2 0.2 1" />
      </material>
    </visual>
  </link>

  <joint name="fr_hx" type="revolute">
    <parent link="base"/>
    <child link="fr_hip"/>
    <axis xyz="1 0 0"/>
    <limit lower="-0.785398" upper="0.785398" effort="0" velocity="0"/>
  </joint>

  <!-- Front Right Upper Leg -->
  <link name="fr_uleg">
    <inertial>
      <origin xyz="-0.005607 0.003877 -0.118199" rpy="0 0 0"/>
      <mass value="0.639"/>
      <inertia ixx="0.0058474" ixy="0" ixz="0" iyy="0.00571186" iyz="0" izz="0.000324584"/>
    </inertial>
    <visual>
      <geometry>
        <mesh filename="package://spot_description/urdf/meshes/fr.uleg.obj"/>
      </geometry>
      <material name="fr_uleg">
        <color rgba="1 0.8431 0 1" />
      </material>
    </visual>
    <collision>
      <origin xyz="0 0 -0.125" rpy="0 0 0"/>
      <geometry>
        <box size="0.125 0.0187 0.0215"/>
      </geometry>
    </collision>
  </link>

  <joint name="fr_hy" type="revolute">
    <parent link="fr_hip"/>
    <child link="fr_uleg"/>
    <axis xyz="0 1 0"/>
    <limit lower="-0.898845" upper="2.24363" effort="0" velocity="0"/>
  </joint>

  <!-- Front Right Lower Leg -->
  <link name="fr_lleg">
    <inertial>
      <origin xyz="0.002781 6.3e-05 -0.142518" rpy="0 0 0"/>
      <mass value="0.207"/>
      <inertia ixx="0.0028579" ixy="0" ixz="0" iyy="0.00285516" iyz="0" izz="3.64431e-05"/>
    </inertial>
    <visual>
      <origin xyz="0 -0.004 0" rpy="0 0 0"/>
      <geometry>
        <mesh filename="package://spot_description/urdf/meshes/fr.lleg.obj"/>
      </geometry>
      <material name="fr_lleg">
        <color rgba="0.2 0.2 0.2 1" />
      </material>
    </visual>
    <collision>
      <origin xyz="0 0 -0.335" rpy="0 0 0"/>
      <geometry>
        <sphere radius="0.0335"/>
      </geometry>
    </collision>
    <collision>
      <origin xyz="0 0 -0.125" rpy="0 0 0"/>
      <geometry>
        <box size="0.125 0.0104 0.008"/>
      </geometry>
    </collision>
  </link>

  <joint name="fr_kn" type="revolute">
    <parent link="fr_uleg"/>
    <child link="fr_lleg"/>
    <axis xyz="0 1 0"/>
    <limit lower="-2.7929" upper="-0.255648" effort="0" velocity="0"/>
  </joint>

  <!-- Hind Left Hip -->
  <link name="hl_hip">
    <inertial>
      <origin xyz="0.022191 0.015144 -1.5e-05" rpy="0 0 0"/>
      <mass value="1.993"/>
      <inertia ixx="0.00558695" ixy="0" ixz="0" iyy="0.00491009" iyz="0" izz="0.00290132"/>
    </inertial>
    <visual>
      <geometry>
        <mesh filename="package://spot_description/urdf/meshes/hl.hip.obj"/>
      </geometry>
      <material name="hl_hip">
        <color rgba="0.2 0.2 0.2 1" />
      </material>
    </visual>
  </link>

  <joint name="hl_hx" type="revolute">
    <parent link="base"/>
    <child link="hl_hip"/>
    <axis xyz="1 0 0"/>
    <limit lower="-0.785398" upper="0.785398" effort="0" velocity="0"/>
  </joint>

  <!-- Hind Left Upper Leg -->
  <link name="hl_uleg">
    <inertial>
      <origin xyz="-0.005607 -0.003877 -0.118199" rpy="0 0 0"/>
      <mass value="0.639"/>
      <inertia ixx="0.0058474" ixy="0" ixz="0" iyy="0.00571186" iyz="0" izz="0.000324584"/>
    </inertial>
    <visual>
      <geometry>
        <mesh filename="package://spot_description/urdf/meshes/hl.uleg.obj"/>
      </geometry>
      <material name="hl_uleg">
        <color rgba="1 0.8431 0 1" />
      </material>
    </visual>
    <collision>
      <origin xyz="0 0 -0.125" rpy="0 0 0"/>
      <geometry>
        <box size="0.125 0.0187 0.0215"/>
      </geometry>
    </collision>
  </link>

  <joint name="hl_hy" type="revolute">
    <parent link="hl_hip"/>
    <child link="hl_uleg"/>
    <axis xyz="0 1 0"/>
    <limit lower="-0.898845" upper="2.29511" effort="0" velocity="0"/>
  </joint>

  <!-- Hind Left Lower Leg -->
  <link name="hl_lleg">
    <inertial>
      <origin xyz="0.002781 6.3e-05 -0.142518" rpy="0 0 0"/>
      <mass value="0.207"/>
      <inertia ixx="0.0028579" ixy="0" ixz="0" iyy="0.00285516" iyz="0" izz="3.64431e-05"/>
    </inertial>
    <visual>
      <geometry>
        <mesh filename="package://spot_description/urdf/meshes/hl.lleg.obj"/>
      </geometry>
      <material name="hl_lleg">
        <color rgba="0.2 0.2 0.2 1" />
      </material>
    </visual>
    <collision>
      <origin xyz="0 0 -0.335" rpy="0 0 0"/>
      <geometry>
        <sphere radius="0.0335"/>
      </geometry>
    </collision>
    <collision>
      <origin xyz="0 0 -0.125" rpy="0 0 0"/>
      <geometry>
        <box size="0.125 0.0104 0.008"/>
      </geometry>
    </collision>
  </link>

  <joint name="hl_kn" type="revolute">
    <parent link="hl_uleg"/>
    <child link="hl_lleg"/>
    <axis xyz="0 1 0"/>
    <limit lower="-2.7929" upper="-0.247067" effort="0" velocity="0"/>
  </joint>

  <!-- Hind Right Hip -->
  <link name="hr_hip">
    <inertial>
      <origin xyz="0.022191 -0.015144 -1.5e-05" rpy="0 0 0"/>
      <mass value="1.993"/>
      <inertia ixx="0.00558695" ixy="0" ixz="0" iyy="0.00491009" iyz="0" izz="0.00290132"/>
    </inertial>
    <visual>
      <geometry>
        <mesh filename="package://spot_description/urdf/meshes/hr.hip.obj"/>
      </geometry>
      <material name="hr_hip">
        <color rgba="0.2 0.2 0.2 1" />
      </material>
    </visual>
  </link>

  <joint name="hr_hx" type="revolute">
    <parent link="base"/>
    <child link="hr_hip"/>
    <axis xyz="1 0 0"/>
    <limit lower="-0.785398" upper="0.785398" effort="0" velocity="0"/>
  </joint>

  <!-- Hind Right Upper Leg -->
  <link name="hr_uleg">
    <inertial>
      <origin xyz="-0.005607 0.003877 -0.118199" rpy="0 0 0"/>
      <mass value="0.639"/>
      <inertia ixx="0.0058474" ixy="0" ixz="0" iyy="0.00571186" iyz="0" izz="0.000324584"/>
    </inertial>
    <visual>
      <geometry>
        <mesh filename="package://spot_description/urdf/meshes/hr.uleg.obj"/>
      </geometry>
      <material name="hr_uleg">
        <color rgba="1 0.8431 0 1" />
      </material>
    </visual>
    <collision>
      <origin xyz="0 0 -0.125" rpy="0 0 0"/>
      <geometry>
        <box size="0.125 0.0187 0.0215"/>
      </geometry>
    </collision>
  </link>

  <joint name="hr_hy" type="revolute">
    <parent link="hr_hip"/>
    <child link="hr_uleg"/>
    <axis xyz="0 1 0"/>
    <limit lower="-0.898845" upper="2.29511" effort="0" velocity="0"/>
  </joint>

  <!-- Hind Right Lower Leg -->
  <link name="hr_lleg">
    <inertial>
      <origin xyz="0.002781 6.3e-05 -0.142518" rpy="0 0 0"/>
      <mass value="0.207"/>
      <inertia ixx="0.0028579" ixy="0" ixz="0" iyy="0.00285516" iyz="0" izz="3.64431e-05"/>
    </inertial>
    <visual>
      <geometry>
        <mesh filename="package://spot_description/urdf/meshes/hr.lleg.obj"/>
      </geometry>
      <material name="hr_lleg">
        <color rgba="0.2 0.2 0.2 1" />
      </material>
    </visual>
    <collision>
      <origin xyz="0 0 -0.335" rpy="0 0 0"/>
      <geometry>
        <sphere radius="0.0335"/>
      </geometry>
    </collision>
    <collision>
      <origin xyz="0 0 -0.125" rpy="0 0 0"/>
      <geometry>
        <box size="0.125 0.0104 0.008"/>
      </geometry>
    </collision>
  </link>

  <joint name="hr_kn" type="revolute">
    <parent link="hr_uleg"/>
    <child link="hr_lleg"/>
    <axis xyz="0 1 0"/>
    <limit lower="-2.7929" upper="-0.248282" effort="0" velocity="0"/>
  </joint>

<!-- ROS2 control tag -->
  <ros2_control name="MujocoSystem" type="system">
    <hardware>
        <plugin>mujoco_ros2_control/MujocoSystem</plugin>
    </hardware>

    <!-- Front Left Leg Joints -->
    <joint name="fl_hx">
        <command_interface name="effort" />
        <state_interface name="position" />
        <state_interface name="velocity" />
        <state_interface name="effort" />
    </joint>

    <joint name="fl_hy">
        <command_interface name="effort" />
        <state_interface name="position" />
        <state_interface name="velocity" />
        <state_interface name="effort" />
    </joint>

    <joint name="fl_kn">
        <command_interface name="effort" />
        <state_interface name="position" />
        <state_interface name="velocity" />
        <state_interface name="effort" />
    </joint>

    <!-- Front Right Leg Joints -->
    <joint name="fr_hx">
        <command_interface name="effort" />
        <state_interface name="position" />
        <state_interface name="velocity" />
        <state_interface name="effort" />
    </joint>

    <joint name="fr_hy">
        <command_interface name="effort" />
        <state_interface name="position" />
        <state_interface name="velocity" />
        <state_interface name="effort" />
    </joint>

    <joint name="fr_kn">
        <command_interface name="effort" />
        <state_interface name="position" />
        <state_interface name="velocity" />
        <state_interface name="effort" />
    </joint>

    <!-- Hind Left Leg Joints -->
    <joint name="hl_hx">
        <command_interface name="effort" />
        <state_interface name="position" />
        <state_interface name="velocity" />
        <state_interface name="effort" />
    </joint>

    <joint name="hl_hy">
        <command_interface name="effort" />
        <state_interface name="position" />
        <state_interface name="velocity" />
        <state_interface name="effort" />
    </joint>

    <joint name="hl_kn">
        <command_interface name="effort" />
        <state_interface name="position" />
        <state_interface name="velocity" />
        <state_interface name="effort" />
    </joint>

    <!-- Hind Right Leg Joints -->
    <joint name="hr_hx">
        <command_interface name="effort" />
        <state_interface name="position" />
        <state_interface name="velocity" />
        <state_interface name="effort" />
    </joint>

    <joint name="hr_hy">
        <command_interface name="effort" />
        <state_interface name="position" />
        <state_interface name="velocity" />
        <state_interface name="effort" />
    </joint>

    <joint name="hr_kn">
        <command_interface name="effort" />
        <state_interface name="position" />
        <state_interface name="velocity" />
        <state_interface name="effort" />
    </joint>
  
  </ros2_control>

</robot>